Workbook

Sheet Timeline
A1: EU AML Package — prospective timeline to live dates (Level 1 + Level 2/3)
A2: Prepared 23 Jul 2026 from AMLA/Commission official sources. Best case = user's 3+3+3 model; Realistic = longer Commission stage. Not legal advice.
A4: LEVEL 1 — agreed texts (in force since 9 Jul 2024)
A5: AMLR — Regulation (EU) 2024/1624 (single rulebook: CDD, BO, PEPs, obliged entities) | H5: Applies 10 Jul 2027 (directly applicable; no transposition)
A6: AMLD6 — Directive (EU) 2024/1640 (supervision, FIUs, BO registers) | H6: Transposition deadline 10 Jul 2027 (Art. 74: BO registers 10 Jul 2026)
A7: AMLAR — Regulation (EU) 2024/1620 (AMLA) | H7: AMLA operational since Jul 2025; direct supervision of ~40 entities from 2028 (selection 2027)
A8: LEVEL 2/3 — AMLA instruments: consultations and projected live dates
A9: # | B9: Type | C9: Legal basis | D9: Instrument | E9: Consult. opens | F9: Consult. closes | G9: Status | H9: AMLA final → EC (best) | I9: EC adoption (best) | J9: Scrutiny ends (best) | K9: LIVE — best case | L9: AMLA final → EC (real.) | M9: EC adoption (real.) | N9: Scrutiny ends (real.) | O9: LIVE — realistic | P9: Risk vs 10 Jul 2027
A10: 1 | B10: RTS | C10: AMLAR 12(7) | D10: Risk assessment for selection for direct supervision | E10: — | F10: — | G10: Final report 18 Dec 2025 (EBA-consulted) | H10: 46009 | I10: =EDATE($H10,Assumptions!$B$7) -> 46099 | J10: =EDATE($I10,Assumptions!$B$8) -> 46191 | K10: =$J10+20 -> 46211 | L10: 46009 | M10: =EDATE($L10,Assumptions!$C$7) -> 46191 | N10: =EDATE($M10,Assumptions!$C$8) -> 46283 | O10: =$N10+30 -> 46313 | P10: =IF($O10>DATE(2027,7,10),"LIVE AFTER APPLICATION DATE",IF($O10>DATE(2027,4,10),"Tight (<3m before application)","OK")) -> OK
A11: 2 | B11: RTS | C11: AMLD 40(2) | D11: Inherent & residual risk profile of obliged entities (financial sector) | E11: — | F11: — | G11: Final report 18 Dec 2025 (EBA-consulted) | H11: 46009 | I11: =EDATE($H11,Assumptions!$B$7) -> 46099 | J11: =EDATE($I11,Assumptions!$B$8) -> 46191 | K11: =$J11+20 -> 46211 | L11: 46009 | M11: =EDATE($L11,Assumptions!$C$7) -> 46191 | N11: =EDATE($M11,Assumptions!$C$8) -> 46283 | O11: =$N11+30 -> 46313 | P11: =IF($O11>DATE(2027,7,10),"LIVE AFTER APPLICATION DATE",IF($O11>DATE(2027,4,10),"Tight (<3m before application)","OK")) -> OK
A12: 3 | B12: ITS | C12: AMLAR 15(3) | D12: Cooperation within supervisory system (direct supervision) | E12: 46007 | F12: 46049 | G12: Consultation closed; final expected Q3 2026 | H12: =EDATE($F12,Assumptions!$B$6) -> 46139 | I12: =EDATE($H12,Assumptions!$B$7) -> 46230 | J12: n/a | K12: =$I12+20 -> 46250 | L12: =EDATE($F12,Assumptions!$C$6) -> 46169 | M12: =EDATE($L12,Assumptions!$C$7) -> 46353 | N12: n/a | O12: =$M12+30 -> 46383 | P12: =IF($O12>DATE(2027,7,10),"LIVE AFTER APPLICATION DATE",IF($O12>DATE(2027,4,10),"Tight (<3m before application)","OK")) -> OK
A13: 4 | B13: RTS | C13: AMLD 53(10) | D13: Pecuniary sanctions, administrative measures, periodic penalty payments | E13: 46062 | F13: 46090 | G13: Consultation closed; final expected Q3 2026 | H13: =EDATE($F13,Assumptions!$B$6) -> 46182 | I13: =EDATE($H13,Assumptions!$B$7) -> 46274 | J13: =EDATE($I13,Assumptions!$B$8) -> 46365 | K13: =$J13+20 -> 46385 | L13: =EDATE($F13,Assumptions!$C$6) -> 46212 | M13: =EDATE($L13,Assumptions!$C$7) -> 46396 | N13: =EDATE($M13,Assumptions!$C$8) -> 46486 | O13: =$N13+30 -> 46516 | P13: =IF($O13>DATE(2027,7,10),"LIVE AFTER APPLICATION DATE",IF($O13>DATE(2027,4,10),"Tight (<3m before application)","OK")) -> Tight (<3m before application)
A14: 5 | B14: RTS | C14: AMLR 28(1) | D14: Customer Due Diligence (standard / simplified / enhanced) | E14: 46062 | F14: 46150 | G14: Consultation closed; final expected Q3 2026 | H14: =EDATE($F14,Assumptions!$B$6) -> 46242 | I14: =EDATE($H14,Assumptions!$B$7) -> 46334 | J14: =EDATE($I14,Assumptions!$B$8) -> 46426 | K14: =$J14+20 -> 46446 | L14: =EDATE($F14,Assumptions!$C$6) -> 46273 | M14: =EDATE($L14,Assumptions!$C$7) -> 46454 | N14: =EDATE($M14,Assumptions!$C$8) -> 46546 | O14: =$N14+30 -> 46576 | P14: =IF($O14>DATE(2027,7,10),"LIVE AFTER APPLICATION DATE",IF($O14>DATE(2027,4,10),"Tight (<3m before application)","OK")) -> Tight (<3m before application)
A15: 6 | B15: RTS | C15: AMLR 19(9) | D15: Business relationships, occasional & linked transactions, lower thresholds | E15: 46062 | F15: 46150 | G15: Consultation closed; final expected Q3 2026 | H15: =EDATE($F15,Assumptions!$B$6) -> 46242 | I15: =EDATE($H15,Assumptions!$B$7) -> 46334 | J15: =EDATE($I15,Assumptions!$B$8) -> 46426 | K15: =$J15+20 -> 46446 | L15: =EDATE($F15,Assumptions!$C$6) -> 46273 | M15: =EDATE($L15,Assumptions!$C$7) -> 46454 | N15: =EDATE($M15,Assumptions!$C$8) -> 46546 | O15: =$N15+30 -> 46576 | P15: =IF($O15>DATE(2027,7,10),"LIVE AFTER APPLICATION DATE",IF($O15>DATE(2027,4,10),"Tight (<3m before application)","OK")) -> Tight (<3m before application)
A16: 7 | B16: RTS | C16: AMLR 16(4), 17(3) | D16: Group-wide minimum requirements; third-country branches/subsidiaries | E16: 46128 | F16: 46188 | G16: Consultation closed; AMLA to submit to EC by 30 Sep 2026 | H16: =EDATE($F16,Assumptions!$B$6) -> 46280 | I16: =EDATE($H16,Assumptions!$B$7) -> 46371 | J16: =EDATE($I16,Assumptions!$B$8) -> 46461 | K16: =$J16+20 -> 46481 | L16: =EDATE($F16,Assumptions!$C$6) -> 46310 | M16: =EDATE($L16,Assumptions!$C$7) -> 46492 | N16: =EDATE($M16,Assumptions!$C$8) -> 46583 | O16: =$N16+30 -> 46613 | P16: =IF($O16>DATE(2027,7,10),"LIVE AFTER APPLICATION DATE",IF($O16>DATE(2027,4,10),"Tight (<3m before application)","OK")) -> LIVE AFTER APPLICATION DATE
A17: 8 | B17: ITS | C17: AMLR 81(1); AMLAR 41(2) | D17: FIU and AMLA reporting to the EPPO | E17: — | F17: 46173 | G17: Consultation closed (hearing 27 May 2026) | H17: =EDATE($F17,Assumptions!$B$6) -> 46265 | I17: =EDATE($H17,Assumptions!$B$7) -> 46356 | J17: n/a | K17: =$I17+20 -> 46376 | L17: =EDATE($F17,Assumptions!$C$6) -> 46295 | M17: =EDATE($L17,Assumptions!$C$7) -> 46476 | N17: n/a | O17: =$M17+30 -> 46506 | P17: =IF($O17>DATE(2027,7,10),"LIVE AFTER APPLICATION DATE",IF($O17>DATE(2027,4,10),"Tight (<3m before application)","OK")) -> Tight (<3m before application)
A18: 9 | B18: ITS | C18: AMLD 31(2) | D18: FIU-to-FIU exchange format | E18: — | F18: 46173 | G18: Consultation closed (hearing 27 May 2026) | H18: =EDATE($F18,Assumptions!$B$6) -> 46265 | I18: =EDATE($H18,Assumptions!$B$7) -> 46356 | J18: n/a | K18: =$I18+20 -> 46376 | L18: =EDATE($F18,Assumptions!$C$6) -> 46295 | M18: =EDATE($L18,Assumptions!$C$7) -> 46476 | N18: n/a | O18: =$M18+30 -> 46506 | P18: =IF($O18>DATE(2027,7,10),"LIVE AFTER APPLICATION DATE",IF($O18>DATE(2027,4,10),"Tight (<3m before application)","OK")) -> Tight (<3m before application)
A19: 10 | B19: RTS | C19: AMLD 46(4) | D19: Home-host supervisory cooperation | E19: — | F19: 46173 | G19: Consultation closed (hearing 28 May 2026) | H19: =EDATE($F19,Assumptions!$B$6) -> 46265 | I19: =EDATE($H19,Assumptions!$B$7) -> 46356 | J19: =EDATE($I19,Assumptions!$B$8) -> 46446 | K19: =$J19+20 -> 46466 | L19: =EDATE($F19,Assumptions!$C$6) -> 46295 | M19: =EDATE($L19,Assumptions!$C$7) -> 46476 | N19: =EDATE($M19,Assumptions!$C$8) -> 46568 | O19: =$N19+30 -> 46598 | P19: =IF($O19>DATE(2027,7,10),"LIVE AFTER APPLICATION DATE",IF($O19>DATE(2027,4,10),"Tight (<3m before application)","OK")) -> LIVE AFTER APPLICATION DATE
A20: 11 | B20: GL | C20: AMLR 10(4) | D20: Business-wide risk assessment | E20: 46128 | F20: 46218 | G20: Consultation open — closes 15 Jul 2026 | H20: =EDATE($F20,Assumptions!$B$10) -> 46310 | I20: n/a | J20: n/a | K20: =MAX($H20,DATE(2027,7,10)) -> 46578 | L20: =EDATE($F20,Assumptions!$C$10) -> 46402 | M20: n/a | N20: n/a | O20: =MAX($L20,DATE(2027,7,10)) -> 46578 | P20: =IF($O20>DATE(2027,7,10),"LIVE AFTER APPLICATION DATE",IF($O20>DATE(2027,4,10),"Tight (<3m before application)","OK")) -> Tight (<3m before application)
A21: 12 | B21: GL | C21: AMLR 26(5) | D21: Ongoing monitoring of business relationships (incl. transaction monitoring) | E21: 46176 | F21: 46268 | G21: Consultation open — closes 3 Sep 2026 | H21: =EDATE($F21,Assumptions!$B$10) -> 46359 | I21: n/a | J21: n/a | K21: =MAX($H21,DATE(2027,7,10)) -> 46578 | L21: =EDATE($F21,Assumptions!$C$10) -> 46449 | M21: n/a | N21: n/a | O21: =MAX($L21,DATE(2027,7,10)) -> 46578 | P21: =IF($O21>DATE(2027,7,10),"LIVE AFTER APPLICATION DATE",IF($O21>DATE(2027,4,10),"Tight (<3m before application)","OK")) -> Tight (<3m before application)
A22: 13 | B22: ITS | C22: AMLR 69(3) | D22: Format for reporting suspicions & providing transaction records (STR) | E22: 46205 | F22: 46285 | G22: Consultation open — closes 20 Sep 2026 | H22: =EDATE($F22,Assumptions!$B$6) -> 46376 | I22: =EDATE($H22,Assumptions!$B$7) -> 46466 | J22: n/a | K22: =$I22+20 -> 46486 | L22: =EDATE($F22,Assumptions!$C$6) -> 46407 | M22: =EDATE($L22,Assumptions!$C$7) -> 46588 | N22: n/a | O22: =$M22+30 -> 46618 | P22: =IF($O22>DATE(2027,7,10),"LIVE AFTER APPLICATION DATE",IF($O22>DATE(2027,4,10),"Tight (<3m before application)","OK")) -> LIVE AFTER APPLICATION DATE
A23: 14 | B23: RTS | C23: AMLD 31(3) | D23: Cross-border information exchange between FIUs | E23: 46209 | F23: 46301 | G23: Consultation open — closes 6 Oct 2026 | H23: =EDATE($F23,Assumptions!$B$6) -> 46393 | I23: =EDATE($H23,Assumptions!$B$7) -> 46483 | J23: =EDATE($I23,Assumptions!$B$8) -> 46574 | K23: =$J23+20 -> 46594 | L23: =EDATE($F23,Assumptions!$C$6) -> 46424 | M23: =EDATE($L23,Assumptions!$C$7) -> 46605 | N23: =EDATE($M23,Assumptions!$C$8) -> 46697 | O23: =$N23+30 -> 46727 | P23: =IF($O23>DATE(2027,7,10),"LIVE AFTER APPLICATION DATE",IF($O23>DATE(2027,4,10),"Tight (<3m before application)","OK")) -> LIVE AFTER APPLICATION DATE
A24: 15 | B24: RTS | C24: AMLAR 11(6) | D24: Central AML/CFT database | E24: — | F24: 46280 | G24: Consultation planned (SPD: Q2 2026, final Q3 2026) | H24: =EDATE($F24,Assumptions!$B$6) -> 46371 | I24: =EDATE($H24,Assumptions!$B$7) -> 46461 | J24: =EDATE($I24,Assumptions!$B$8) -> 46553 | K24: =$J24+20 -> 46573 | L24: =EDATE($F24,Assumptions!$C$6) -> 46402 | M24: =EDATE($L24,Assumptions!$C$7) -> 46583 | N24: =EDATE($M24,Assumptions!$C$8) -> 46675 | O24: =$N24+30 -> 46705 | P24: =IF($O24>DATE(2027,7,10),"LIVE AFTER APPLICATION DATE",IF($O24>DATE(2027,4,10),"Tight (<3m before application)","OK")) -> LIVE AFTER APPLICATION DATE
A25: 16 | B25: GL | C25: AMLR 20(3) | D25: Risk variables & risk factors (business relationships / occasional transactions) | E25: — | F25: 46371 | G25: Consultation planned (SPD: Q3 2026, final Q4 2026) | H25: =EDATE($F25,Assumptions!$B$10) -> 46461 | I25: n/a | J25: n/a | K25: =MAX($H25,DATE(2027,7,10)) -> 46578 | L25: =EDATE($F25,Assumptions!$C$10) -> 46553 | M25: n/a | N25: n/a | O25: =MAX($L25,DATE(2027,7,10)) -> 46578 | P25: =IF($O25>DATE(2027,7,10),"LIVE AFTER APPLICATION DATE",IF($O25>DATE(2027,4,10),"Tight (<3m before application)","OK")) -> Tight (<3m before application)
A26: 17 | B26: RTS | C26: AMLD 41(2) | D26: Central contact point — criteria & functions | E26: — | F26: 46371 | G26: Consultation planned (SPD: Q3 2026, final Q4 2026) | H26: =EDATE($F26,Assumptions!$B$6) -> 46461 | I26: =EDATE($H26,Assumptions!$B$7) -> 46553 | J26: =EDATE($I26,Assumptions!$B$8) -> 46645 | K26: =$J26+20 -> 46665 | L26: =EDATE($F26,Assumptions!$C$6) -> 46492 | M26: =EDATE($L26,Assumptions!$C$7) -> 46675 | N26: =EDATE($M26,Assumptions!$C$8) -> 46767 | O26: =$N26+30 -> 46797 | P26: =IF($O26>DATE(2027,7,10),"LIVE AFTER APPLICATION DATE",IF($O26>DATE(2027,4,10),"Tight (<3m before application)","OK")) -> LIVE AFTER APPLICATION DATE
A27: 18 | B27: RTS | C27: AMLD 40(2) | D27: Risk profile of obliged entities — non-financial sector | E27: — | F27: 46371 | G27: Consultation planned (SPD: Q3 2026, final Q4 2026) | H27: =EDATE($F27,Assumptions!$B$6) -> 46461 | I27: =EDATE($H27,Assumptions!$B$7) -> 46553 | J27: =EDATE($I27,Assumptions!$B$8) -> 46645 | K27: =$J27+20 -> 46665 | L27: =EDATE($F27,Assumptions!$C$6) -> 46492 | M27: =EDATE($L27,Assumptions!$C$7) -> 46675 | N27: =EDATE($M27,Assumptions!$C$8) -> 46767 | O27: =$N27+30 -> 46797 | P27: =IF($O27>DATE(2027,7,10),"LIVE AFTER APPLICATION DATE",IF($O27>DATE(2027,4,10),"Tight (<3m before application)","OK")) -> LIVE AFTER APPLICATION DATE
A28: 19 | B28: GL | C28: AMLD 53(11) | D28: Base amounts of pecuniary sanctions (per breach / entity category) | E28: — | F28: 46371 | G28: Consultation planned (SPD: Q2 2026, final Q4 2026) | H28: =EDATE($F28,Assumptions!$B$10) -> 46461 | I28: n/a | J28: n/a | K28: =MAX($H28,DATE(2027,7,10)) -> 46578 | L28: =EDATE($F28,Assumptions!$C$10) -> 46553 | M28: n/a | N28: n/a | O28: =MAX($L28,DATE(2027,7,10)) -> 46578 | P28: =IF($O28>DATE(2027,7,10),"LIVE AFTER APPLICATION DATE",IF($O28>DATE(2027,4,10),"Tight (<3m before application)","OK")) -> Tight (<3m before application)
A29: 20 | B29: RTS | C29: AMLD 49(14), 50(13) | D29: AML/CFT supervisory colleges (financial & non-financial) | E29: — | F29: 46461 | G29: Consultation planned (SPD: Q4 2026, final Q1 2027) | H29: =EDATE($F29,Assumptions!$B$6) -> 46553 | I29: =EDATE($H29,Assumptions!$B$7) -> 46645 | J29: =EDATE($I29,Assumptions!$B$8) -> 46736 | K29: =$J29+20 -> 46756 | L29: =EDATE($F29,Assumptions!$C$6) -> 46583 | M29: =EDATE($L29,Assumptions!$C$7) -> 46767 | N29: =EDATE($M29,Assumptions!$C$8) -> 46858 | O29: =$N29+30 -> 46888 | P29: =IF($O29>DATE(2027,7,10),"LIVE AFTER APPLICATION DATE",IF($O29>DATE(2027,4,10),"Tight (<3m before application)","OK")) -> LIVE AFTER APPLICATION DATE
A30: 21 | B30: GL | C30: AMLR 9(4) | D30: Internal policies, procedures and controls | E30: — | F30: 46553 | G30: Consultation planned (SPD: Q1 2027, final Q2 2027) | H30: =EDATE($F30,Assumptions!$B$10) -> 46645 | I30: n/a | J30: n/a | K30: =MAX($H30,DATE(2027,7,10)) -> 46645 | L30: =EDATE($F30,Assumptions!$C$10) -> 46736 | M30: n/a | N30: n/a | O30: =MAX($L30,DATE(2027,7,10)) -> 46736 | P30: =IF($O30>DATE(2027,7,10),"LIVE AFTER APPLICATION DATE",IF($O30>DATE(2027,4,10),"Tight (<3m before application)","OK")) -> LIVE AFTER APPLICATION DATE
A32: Blue = hardcoded official dates; blue italic = estimated (AMLA SPD planning quarters). Rows 15–21 are the pipeline: consultations not yet opened — dates are indicative. GL 'live' = later of final publication and 10 Jul 2027 (usual application alignment).

Sheet Gantt
A1: Visual timeline (monthly) — C = consultation, P = Level 2 process (best case), S = potential slippage (best → realistic)
A2: Column of 10 Jul 2027 (AMLR application) highlighted in dark red.
A4: # | B4: Instrument | C4: Type | D4: 45992 | E4: 46023 | F4: 46054 | G4: 46082 | H4: 46113 | I4: 46143 | J4: 46174 | K4: 46204 | L4: 46235 | M4: 46266 | N4: 46296 | O4: 46327 | P4: 46357 | Q4: 46388 | R4: 46419 | S4: 46447 | T4: 46478 | U4: 46508 | V4: 46539 | W4: 46569 | X4: 46600 | Y4: 46631 | Z4: 46661 | AA4: 46692 | AB4: 46722 | AC4: 46753 | AD4: 46784 | AE4: 46813 | AF4: 46844 | AG4: 46874 | AH4: 46905
A5: 1 | B5: Risk assessment for selection for direct supervision | C5: RTS | D5: =IF(AND(ISNUMBER(Timeline!$E10),ISNUMBER(Timeline!$F10),D$4<=Timeline!$F10,EOMONTH(D$4,0)>=Timeline!$E10),"C",IF(AND(ISNUMBER(Timeline!$F10),ISNUMBER(Timeline!$K10),D$4<=Timeline!$K10,EOMONTH(D$4,0)>Timeline!$F10),"P",IF(AND(ISNUMBER(Timeline!$H10),ISNUMBER(Timeline!$K10),NOT(ISNUMBER(Timeline!$F10)),D$4<=Timeline!$K10,EOMONTH(D$4,0)>=Timeline!$H10),"P",IF(AND(ISNUMBER(Timeline!$K10),ISNUMBER(Timeline!$O10),D$4<=Timeline!$O10,EOMONTH(D$4,0)>Timeline!$K10),"S","")))) -> P | E5: =IF(AND(ISNUMBER(Timeline!$E10),ISNUMBER(Timeline!$F10),E$4<=Timeline!$F10,EOMONTH(E$4,0)>=Timeline!$E10),"C",IF(AND(ISNUMBER(Timeline!$F10),ISNUMBER(Timeline!$K10),E$4<=Timeline!$K10,EOMONTH(E$4,0)>Timeline!$F10),"P",IF(AND(ISNUMBER(Timeline!$H10),ISNUMBER(Timeline!$K10),NOT(ISNUMBER(Timeline!$F10)),E$4<=Timeline!$K10,EOMONTH(E$4,0)>=Timeline!$H10),"P",IF(AND(ISNUMBER(Timeline!$K10),ISNUMBER(Timeline!$O10),E$4<=Timeline!$O10,EOMONTH(E$4,0)>Timeline!$K10),"S","")))) -> P | F5: =IF(AND(ISNUMBER(Timeline!$E10),ISNUMBER(Timeline!$F10),F$4<=Timeline!$F10,EOMONTH(F$4,0)>=Timeline!$E10),"C",IF(AND(ISNUMBER(Timeline!$F10),ISNUMBER(Timeline!$K10),F$4<=Timeline!$K10,EOMONTH(F$4,0)>Timeline!$F10),"P",IF(AND(ISNUMBER(Timeline!$H10),ISNUMBER(Timeline!$K10),NOT(ISNUMBER(Timeline!$F10)),F$4<=Timeline!$K10,EOMONTH(F$4,0)>=Timeline!$H10),"P",IF(AND(ISNUMBER(Timeline!$K10),ISNUMBER(Timeline!$O10),F$4<=Timeline!$O10,EOMONTH(F$4,0)>Timeline!$K10),"S","")))) -> P | G5: =IF(AND(ISNUMBER(Timeline!$E10),ISNUMBER(Timeline!$F10),G$4<=Timeline!$F10,EOMONTH(G$4,0)>=Timeline!$E10),"C",IF(AND(ISNUMBER(Timeline!$F10),ISNUMBER(Timeline!$K10),G$4<=Timeline!$K10,EOMONTH(G$4,0)>Timeline!$F10),"P",IF(AND(ISNUMBER(Timeline!$H10),ISNUMBER(Timeline!$K10),NOT(ISNUMBER(Timeline!$F10)),G$4<=Timeline!$K10,EOMONTH(G$4,0)>=Timeline!$H10),"P",IF(AND(ISNUMBER(Timeline!$K10),ISNUMBER(Timeline!$O10),G$4<=Timeline!$O10,EOMONTH(G$4,0)>Timeline!$K10),"S","")))) -> P | H5: =IF(AND(ISNUMBER(Timeline!$E10),ISNUMBER(Timeline!$F10),H$4<=Timeline!$F10,EOMONTH(H$4,0)>=Timeline!$E10),"C",IF(AND(ISNUMBER(Timeline!$F10),ISNUMBER(Timeline!$K10),H$4<=Timeline!$K10,EOMONTH(H$4,0)>Timeline!$F10),"P",IF(AND(ISNUMBER(Timeline!$H10),ISNUMBER(Timeline!$K10),NOT(ISNUMBER(Timeline!$F10)),H$4<=Timeline!$K10,EOMONTH(H$4,0)>=Timeline!$H10),"P",IF(AND(ISNUMBER(Timeline!$K10),ISNUMBER(Timeline!$O10),H$4<=Timeline!$O10,EOMONTH(H$4,0)>Timeline!$K10),"S","")))) -> P | I5: =IF(AND(ISNUMBER(Timeline!$E10),ISNUMBER(Timeline!$F10),I$4<=Timeline!$F10,EOMONTH(I$4,0)>=Timeline!$E10),"C",IF(AND(ISNUMBER(Timeline!$F10),ISNUMBER(Timeline!$K10),I$4<=Timeline!$K10,EOMONTH(I$4,0)>Timeline!$F10),"P",IF(AND(ISNUMBER(Timeline!$H10),ISNUMBER(Timeline!$K10),NOT(ISNUMBER(Timeline!$F10)),I$4<=Timeline!$K10,EOMONTH(I$4,0)>=Timeline!$H10),"P",IF(AND(ISNUMBER(Timeline!$K10),ISNUMBER(Timeline!$O10),I$4<=Timeline!$O10,EOMONTH(I$4,0)>Timeline!$K10),"S","")))) -> P | J5: =IF(AND(ISNUMBER(Timeline!$E10),ISNUMBER(Timeline!$F10),J$4<=Timeline!$F10,EOMONTH(J$4,0)>=Timeline!$E10),"C",IF(AND(ISNUMBER(Timeline!$F10),ISNUMBER(Timeline!$K10),J$4<=Timeline!$K10,EOMONTH(J$4,0)>Timeline!$F10),"P",IF(AND(ISNUMBER(Timeline!$H10),ISNUMBER(Timeline!$K10),NOT(ISNUMBER(Timeline!$F10)),J$4<=Timeline!$K10,EOMONTH(J$4,0)>=Timeline!$H10),"P",IF(AND(ISNUMBER(Timeline!$K10),ISNUMBER(Timeline!$O10),J$4<=Timeline!$O10,EOMONTH(J$4,0)>Timeline!$K10),"S","")))) -> P | K5: =IF(AND(ISNUMBER(Timeline!$E10),ISNUMBER(Timeline!$F10),K$4<=Timeline!$F10,EOMONTH(K$4,0)>=Timeline!$E10),"C",IF(AND(ISNUMBER(Timeline!$F10),ISNUMBER(Timeline!$K10),K$4<=Timeline!$K10,EOMONTH(K$4,0)>Timeline!$F10),"P",IF(AND(ISNUMBER(Timeline!$H10),ISNUMBER(Timeline!$K10),NOT(ISNUMBER(Timeline!$F10)),K$4<=Timeline!$K10,EOMONTH(K$4,0)>=Timeline!$H10),"P",IF(AND(ISNUMBER(Timeline!$K10),ISNUMBER(Timeline!$O10),K$4<=Timeline!$O10,EOMONTH(K$4,0)>Timeline!$K10),"S","")))) -> P | ... AH5: =IF(AND(ISNUMBER(Timeline!$E10),ISNUMBER(Timeline!$F10),AH$4<=Timeline!$F10,EOMONTH(AH$4,0)>=Timeline!$E10),"C",IF(AND(ISNUMBER(Timeline!$F10),ISNUMBER(Timeline!$K10),AH$4<=Timeline!$K10,EOMONTH(AH$4,0)>Timeline!$F10),"P",IF(AND(ISNUMBER(Timeline!$H10),ISNUMBER(Timeline!$K10),NOT(ISNUMBER(Timeline!$F10)),AH$4<=Timeline!$K10,EOMONTH(AH$4,0)>=Timeline!$H10),"P",IF(AND(ISNUMBER(Timeline!$K10),ISNUMBER(Timeline!$O10),AH$4<=Timeline!$O10,EOMONTH(AH$4,0)>Timeline!$K10),"S",""))))
A6: 2 | B6: Inherent & residual risk profile of obliged entities (financial sector) | C6: RTS | D6: =IF(AND(ISNUMBER(Timeline!$E11),ISNUMBER(Timeline!$F11),D$4<=Timeline!$F11,EOMONTH(D$4,0)>=Timeline!$E11),"C",IF(AND(ISNUMBER(Timeline!$F11),ISNUMBER(Timeline!$K11),D$4<=Timeline!$K11,EOMONTH(D$4,0)>Timeline!$F11),"P",IF(AND(ISNUMBER(Timeline!$H11),ISNUMBER(Timeline!$K11),NOT(ISNUMBER(Timeline!$F11)),D$4<=Timeline!$K11,EOMONTH(D$4,0)>=Timeline!$H11),"P",IF(AND(ISNUMBER(Timeline!$K11),ISNUMBER(Timeline!$O11),D$4<=Timeline!$O11,EOMONTH(D$4,0)>Timeline!$K11),"S","")))) -> P | E6: =IF(AND(ISNUMBER(Timeline!$E11),ISNUMBER(Timeline!$F11),E$4<=Timeline!$F11,EOMONTH(E$4,0)>=Timeline!$E11),"C",IF(AND(ISNUMBER(Timeline!$F11),ISNUMBER(Timeline!$K11),E$4<=Timeline!$K11,EOMONTH(E$4,0)>Timeline!$F11),"P",IF(AND(ISNUMBER(Timeline!$H11),ISNUMBER(Timeline!$K11),NOT(ISNUMBER(Timeline!$F11)),E$4<=Timeline!$K11,EOMONTH(E$4,0)>=Timeline!$H11),"P",IF(AND(ISNUMBER(Timeline!$K11),ISNUMBER(Timeline!$O11),E$4<=Timeline!$O11,EOMONTH(E$4,0)>Timeline!$K11),"S","")))) -> P | F6: =IF(AND(ISNUMBER(Timeline!$E11),ISNUMBER(Timeline!$F11),F$4<=Timeline!$F11,EOMONTH(F$4,0)>=Timeline!$E11),"C",IF(AND(ISNUMBER(Timeline!$F11),ISNUMBER(Timeline!$K11),F$4<=Timeline!$K11,EOMONTH(F$4,0)>Timeline!$F11),"P",IF(AND(ISNUMBER(Timeline!$H11),ISNUMBER(Timeline!$K11),NOT(ISNUMBER(Timeline!$F11)),F$4<=Timeline!$K11,EOMONTH(F$4,0)>=Timeline!$H11),"P",IF(AND(ISNUMBER(Timeline!$K11),ISNUMBER(Timeline!$O11),F$4<=Timeline!$O11,EOMONTH(F$4,0)>Timeline!$K11),"S","")))) -> P | G6: =IF(AND(ISNUMBER(Timeline!$E11),ISNUMBER(Timeline!$F11),G$4<=Timeline!$F11,EOMONTH(G$4,0)>=Timeline!$E11),"C",IF(AND(ISNUMBER(Timeline!$F11),ISNUMBER(Timeline!$K11),G$4<=Timeline!$K11,EOMONTH(G$4,0)>Timeline!$F11),"P",IF(AND(ISNUMBER(Timeline!$H11),ISNUMBER(Timeline!$K11),NOT(ISNUMBER(Timeline!$F11)),G$4<=Timeline!$K11,EOMONTH(G$4,0)>=Timeline!$H11),"P",IF(AND(ISNUMBER(Timeline!$K11),ISNUMBER(Timeline!$O11),G$4<=Timeline!$O11,EOMONTH(G$4,0)>Timeline!$K11),"S","")))) -> P | H6: =IF(AND(ISNUMBER(Timeline!$E11),ISNUMBER(Timeline!$F11),H$4<=Timeline!$F11,EOMONTH(H$4,0)>=Timeline!$E11),"C",IF(AND(ISNUMBER(Timeline!$F11),ISNUMBER(Timeline!$K11),H$4<=Timeline!$K11,EOMONTH(H$4,0)>Timeline!$F11),"P",IF(AND(ISNUMBER(Timeline!$H11),ISNUMBER(Timeline!$K11),NOT(ISNUMBER(Timeline!$F11)),H$4<=Timeline!$K11,EOMONTH(H$4,0)>=Timeline!$H11),"P",IF(AND(ISNUMBER(Timeline!$K11),ISNUMBER(Timeline!$O11),H$4<=Timeline!$O11,EOMONTH(H$4,0)>Timeline!$K11),"S","")))) -> P | I6: =IF(AND(ISNUMBER(Timeline!$E11),ISNUMBER(Timeline!$F11),I$4<=Timeline!$F11,EOMONTH(I$4,0)>=Timeline!$E11),"C",IF(AND(ISNUMBER(Timeline!$F11),ISNUMBER(Timeline!$K11),I$4<=Timeline!$K11,EOMONTH(I$4,0)>Timeline!$F11),"P",IF(AND(ISNUMBER(Timeline!$H11),ISNUMBER(Timeline!$K11),NOT(ISNUMBER(Timeline!$F11)),I$4<=Timeline!$K11,EOMONTH(I$4,0)>=Timeline!$H11),"P",IF(AND(ISNUMBER(Timeline!$K11),ISNUMBER(Timeline!$O11),I$4<=Timeline!$O11,EOMONTH(I$4,0)>Timeline!$K11),"S","")))) -> P | J6: =IF(AND(ISNUMBER(Timeline!$E11),ISNUMBER(Timeline!$F11),J$4<=Timeline!$F11,EOMONTH(J$4,0)>=Timeline!$E11),"C",IF(AND(ISNUMBER(Timeline!$F11),ISNUMBER(Timeline!$K11),J$4<=Timeline!$K11,EOMONTH(J$4,0)>Timeline!$F11),"P",IF(AND(ISNUMBER(Timeline!$H11),ISNUMBER(Timeline!$K11),NOT(ISNUMBER(Timeline!$F11)),J$4<=Timeline!$K11,EOMONTH(J$4,0)>=Timeline!$H11),"P",IF(AND(ISNUMBER(Timeline!$K11),ISNUMBER(Timeline!$O11),J$4<=Timeline!$O11,EOMONTH(J$4,0)>Timeline!$K11),"S","")))) -> P | K6: =IF(AND(ISNUMBER(Timeline!$E11),ISNUMBER(Timeline!$F11),K$4<=Timeline!$F11,EOMONTH(K$4,0)>=Timeline!$E11),"C",IF(AND(ISNUMBER(Timeline!$F11),ISNUMBER(Timeline!$K11),K$4<=Timeline!$K11,EOMONTH(K$4,0)>Timeline!$F11),"P",IF(AND(ISNUMBER(Timeline!$H11),ISNUMBER(Timeline!$K11),NOT(ISNUMBER(Timeline!$F11)),K$4<=Timeline!$K11,EOMONTH(K$4,0)>=Timeline!$H11),"P",IF(AND(ISNUMBER(Timeline!$K11),ISNUMBER(Timeline!$O11),K$4<=Timeline!$O11,EOMONTH(K$4,0)>Timeline!$K11),"S","")))) -> P | ... AH6: =IF(AND(ISNUMBER(Timeline!$E11),ISNUMBER(Timeline!$F11),AH$4<=Timeline!$F11,EOMONTH(AH$4,0)>=Timeline!$E11),"C",IF(AND(ISNUMBER(Timeline!$F11),ISNUMBER(Timeline!$K11),AH$4<=Timeline!$K11,EOMONTH(AH$4,0)>Timeline!$F11),"P",IF(AND(ISNUMBER(Timeline!$H11),ISNUMBER(Timeline!$K11),NOT(ISNUMBER(Timeline!$F11)),AH$4<=Timeline!$K11,EOMONTH(AH$4,0)>=Timeline!$H11),"P",IF(AND(ISNUMBER(Timeline!$K11),ISNUMBER(Timeline!$O11),AH$4<=Timeline!$O11,EOMONTH(AH$4,0)>Timeline!$K11),"S",""))))
A7: 3 | B7: Cooperation within supervisory system (direct supervision) | C7: ITS | D7: =IF(AND(ISNUMBER(Timeline!$E12),ISNUMBER(Timeline!$F12),D$4<=Timeline!$F12,EOMONTH(D$4,0)>=Timeline!$E12),"C",IF(AND(ISNUMBER(Timeline!$F12),ISNUMBER(Timeline!$K12),D$4<=Timeline!$K12,EOMONTH(D$4,0)>Timeline!$F12),"P",IF(AND(ISNUMBER(Timeline!$H12),ISNUMBER(Timeline!$K12),NOT(ISNUMBER(Timeline!$F12)),D$4<=Timeline!$K12,EOMONTH(D$4,0)>=Timeline!$H12),"P",IF(AND(ISNUMBER(Timeline!$K12),ISNUMBER(Timeline!$O12),D$4<=Timeline!$O12,EOMONTH(D$4,0)>Timeline!$K12),"S","")))) -> C | E7: =IF(AND(ISNUMBER(Timeline!$E12),ISNUMBER(Timeline!$F12),E$4<=Timeline!$F12,EOMONTH(E$4,0)>=Timeline!$E12),"C",IF(AND(ISNUMBER(Timeline!$F12),ISNUMBER(Timeline!$K12),E$4<=Timeline!$K12,EOMONTH(E$4,0)>Timeline!$F12),"P",IF(AND(ISNUMBER(Timeline!$H12),ISNUMBER(Timeline!$K12),NOT(ISNUMBER(Timeline!$F12)),E$4<=Timeline!$K12,EOMONTH(E$4,0)>=Timeline!$H12),"P",IF(AND(ISNUMBER(Timeline!$K12),ISNUMBER(Timeline!$O12),E$4<=Timeline!$O12,EOMONTH(E$4,0)>Timeline!$K12),"S","")))) -> C | F7: =IF(AND(ISNUMBER(Timeline!$E12),ISNUMBER(Timeline!$F12),F$4<=Timeline!$F12,EOMONTH(F$4,0)>=Timeline!$E12),"C",IF(AND(ISNUMBER(Timeline!$F12),ISNUMBER(Timeline!$K12),F$4<=Timeline!$K12,EOMONTH(F$4,0)>Timeline!$F12),"P",IF(AND(ISNUMBER(Timeline!$H12),ISNUMBER(Timeline!$K12),NOT(ISNUMBER(Timeline!$F12)),F$4<=Timeline!$K12,EOMONTH(F$4,0)>=Timeline!$H12),"P",IF(AND(ISNUMBER(Timeline!$K12),ISNUMBER(Timeline!$O12),F$4<=Timeline!$O12,EOMONTH(F$4,0)>Timeline!$K12),"S","")))) -> P | G7: =IF(AND(ISNUMBER(Timeline!$E12),ISNUMBER(Timeline!$F12),G$4<=Timeline!$F12,EOMONTH(G$4,0)>=Timeline!$E12),"C",IF(AND(ISNUMBER(Timeline!$F12),ISNUMBER(Timeline!$K12),G$4<=Timeline!$K12,EOMONTH(G$4,0)>Timeline!$F12),"P",IF(AND(ISNUMBER(Timeline!$H12),ISNUMBER(Timeline!$K12),NOT(ISNUMBER(Timeline!$F12)),G$4<=Timeline!$K12,EOMONTH(G$4,0)>=Timeline!$H12),"P",IF(AND(ISNUMBER(Timeline!$K12),ISNUMBER(Timeline!$O12),G$4<=Timeline!$O12,EOMONTH(G$4,0)>Timeline!$K12),"S","")))) -> P | H7: =IF(AND(ISNUMBER(Timeline!$E12),ISNUMBER(Timeline!$F12),H$4<=Timeline!$F12,EOMONTH(H$4,0)>=Timeline!$E12),"C",IF(AND(ISNUMBER(Timeline!$F12),ISNUMBER(Timeline!$K12),H$4<=Timeline!$K12,EOMONTH(H$4,0)>Timeline!$F12),"P",IF(AND(ISNUMBER(Timeline!$H12),ISNUMBER(Timeline!$K12),NOT(ISNUMBER(Timeline!$F12)),H$4<=Timeline!$K12,EOMONTH(H$4,0)>=Timeline!$H12),"P",IF(AND(ISNUMBER(Timeline!$K12),ISNUMBER(Timeline!$O12),H$4<=Timeline!$O12,EOMONTH(H$4,0)>Timeline!$K12),"S","")))) -> P | I7: =IF(AND(ISNUMBER(Timeline!$E12),ISNUMBER(Timeline!$F12),I$4<=Timeline!$F12,EOMONTH(I$4,0)>=Timeline!$E12),"C",IF(AND(ISNUMBER(Timeline!$F12),ISNUMBER(Timeline!$K12),I$4<=Timeline!$K12,EOMONTH(I$4,0)>Timeline!$F12),"P",IF(AND(ISNUMBER(Timeline!$H12),ISNUMBER(Timeline!$K12),NOT(ISNUMBER(Timeline!$F12)),I$4<=Timeline!$K12,EOMONTH(I$4,0)>=Timeline!$H12),"P",IF(AND(ISNUMBER(Timeline!$K12),ISNUMBER(Timeline!$O12),I$4<=Timeline!$O12,EOMONTH(I$4,0)>Timeline!$K12),"S","")))) -> P | J7: =IF(AND(ISNUMBER(Timeline!$E12),ISNUMBER(Timeline!$F12),J$4<=Timeline!$F12,EOMONTH(J$4,0)>=Timeline!$E12),"C",IF(AND(ISNUMBER(Timeline!$F12),ISNUMBER(Timeline!$K12),J$4<=Timeline!$K12,EOMONTH(J$4,0)>Timeline!$F12),"P",IF(AND(ISNUMBER(Timeline!$H12),ISNUMBER(Timeline!$K12),NOT(ISNUMBER(Timeline!$F12)),J$4<=Timeline!$K12,EOMONTH(J$4,0)>=Timeline!$H12),"P",IF(AND(ISNUMBER(Timeline!$K12),ISNUMBER(Timeline!$O12),J$4<=Timeline!$O12,EOMONTH(J$4,0)>Timeline!$K12),"S","")))) -> P | K7: =IF(AND(ISNUMBER(Timeline!$E12),ISNUMBER(Timeline!$F12),K$4<=Timeline!$F12,EOMONTH(K$4,0)>=Timeline!$E12),"C",IF(AND(ISNUMBER(Timeline!$F12),ISNUMBER(Timeline!$K12),K$4<=Timeline!$K12,EOMONTH(K$4,0)>Timeline!$F12),"P",IF(AND(ISNUMBER(Timeline!$H12),ISNUMBER(Timeline!$K12),NOT(ISNUMBER(Timeline!$F12)),K$4<=Timeline!$K12,EOMONTH(K$4,0)>=Timeline!$H12),"P",IF(AND(ISNUMBER(Timeline!$K12),ISNUMBER(Timeline!$O12),K$4<=Timeline!$O12,EOMONTH(K$4,0)>Timeline!$K12),"S","")))) -> P | ... AH7: =IF(AND(ISNUMBER(Timeline!$E12),ISNUMBER(Timeline!$F12),AH$4<=Timeline!$F12,EOMONTH(AH$4,0)>=Timeline!$E12),"C",IF(AND(ISNUMBER(Timeline!$F12),ISNUMBER(Timeline!$K12),AH$4<=Timeline!$K12,EOMONTH(AH$4,0)>Timeline!$F12),"P",IF(AND(ISNUMBER(Timeline!$H12),ISNUMBER(Timeline!$K12),NOT(ISNUMBER(Timeline!$F12)),AH$4<=Timeline!$K12,EOMONTH(AH$4,0)>=Timeline!$H12),"P",IF(AND(ISNUMBER(Timeline!$K12),ISNUMBER(Timeline!$O12),AH$4<=Timeline!$O12,EOMONTH(AH$4,0)>Timeline!$K12),"S",""))))
A8: 4 | B8: Pecuniary sanctions, administrative measures, periodic penalty payments | C8: RTS | D8: =IF(AND(ISNUMBER(Timeline!$E13),ISNUMBER(Timeline!$F13),D$4<=Timeline!$F13,EOMONTH(D$4,0)>=Timeline!$E13),"C",IF(AND(ISNUMBER(Timeline!$F13),ISNUMBER(Timeline!$K13),D$4<=Timeline!$K13,EOMONTH(D$4,0)>Timeline!$F13),"P",IF(AND(ISNUMBER(Timeline!$H13),ISNUMBER(Timeline!$K13),NOT(ISNUMBER(Timeline!$F13)),D$4<=Timeline!$K13,EOMONTH(D$4,0)>=Timeline!$H13),"P",IF(AND(ISNUMBER(Timeline!$K13),ISNUMBER(Timeline!$O13),D$4<=Timeline!$O13,EOMONTH(D$4,0)>Timeline!$K13),"S","")))) | E8: =IF(AND(ISNUMBER(Timeline!$E13),ISNUMBER(Timeline!$F13),E$4<=Timeline!$F13,EOMONTH(E$4,0)>=Timeline!$E13),"C",IF(AND(ISNUMBER(Timeline!$F13),ISNUMBER(Timeline!$K13),E$4<=Timeline!$K13,EOMONTH(E$4,0)>Timeline!$F13),"P",IF(AND(ISNUMBER(Timeline!$H13),ISNUMBER(Timeline!$K13),NOT(ISNUMBER(Timeline!$F13)),E$4<=Timeline!$K13,EOMONTH(E$4,0)>=Timeline!$H13),"P",IF(AND(ISNUMBER(Timeline!$K13),ISNUMBER(Timeline!$O13),E$4<=Timeline!$O13,EOMONTH(E$4,0)>Timeline!$K13),"S","")))) | F8: =IF(AND(ISNUMBER(Timeline!$E13),ISNUMBER(Timeline!$F13),F$4<=Timeline!$F13,EOMONTH(F$4,0)>=Timeline!$E13),"C",IF(AND(ISNUMBER(Timeline!$F13),ISNUMBER(Timeline!$K13),F$4<=Timeline!$K13,EOMONTH(F$4,0)>Timeline!$F13),"P",IF(AND(ISNUMBER(Timeline!$H13),ISNUMBER(Timeline!$K13),NOT(ISNUMBER(Timeline!$F13)),F$4<=Timeline!$K13,EOMONTH(F$4,0)>=Timeline!$H13),"P",IF(AND(ISNUMBER(Timeline!$K13),ISNUMBER(Timeline!$O13),F$4<=Timeline!$O13,EOMONTH(F$4,0)>Timeline!$K13),"S","")))) -> C | G8: =IF(AND(ISNUMBER(Timeline!$E13),ISNUMBER(Timeline!$F13),G$4<=Timeline!$F13,EOMONTH(G$4,0)>=Timeline!$E13),"C",IF(AND(ISNUMBER(Timeline!$F13),ISNUMBER(Timeline!$K13),G$4<=Timeline!$K13,EOMONTH(G$4,0)>Timeline!$F13),"P",IF(AND(ISNUMBER(Timeline!$H13),ISNUMBER(Timeline!$K13),NOT(ISNUMBER(Timeline!$F13)),G$4<=Timeline!$K13,EOMONTH(G$4,0)>=Timeline!$H13),"P",IF(AND(ISNUMBER(Timeline!$K13),ISNUMBER(Timeline!$O13),G$4<=Timeline!$O13,EOMONTH(G$4,0)>Timeline!$K13),"S","")))) -> C | H8: =IF(AND(ISNUMBER(Timeline!$E13),ISNUMBER(Timeline!$F13),H$4<=Timeline!$F13,EOMONTH(H$4,0)>=Timeline!$E13),"C",IF(AND(ISNUMBER(Timeline!$F13),ISNUMBER(Timeline!$K13),H$4<=Timeline!$K13,EOMONTH(H$4,0)>Timeline!$F13),"P",IF(AND(ISNUMBER(Timeline!$H13),ISNUMBER(Timeline!$K13),NOT(ISNUMBER(Timeline!$F13)),H$4<=Timeline!$K13,EOMONTH(H$4,0)>=Timeline!$H13),"P",IF(AND(ISNUMBER(Timeline!$K13),ISNUMBER(Timeline!$O13),H$4<=Timeline!$O13,EOMONTH(H$4,0)>Timeline!$K13),"S","")))) -> P | I8: =IF(AND(ISNUMBER(Timeline!$E13),ISNUMBER(Timeline!$F13),I$4<=Timeline!$F13,EOMONTH(I$4,0)>=Timeline!$E13),"C",IF(AND(ISNUMBER(Timeline!$F13),ISNUMBER(Timeline!$K13),I$4<=Timeline!$K13,EOMONTH(I$4,0)>Timeline!$F13),"P",IF(AND(ISNUMBER(Timeline!$H13),ISNUMBER(Timeline!$K13),NOT(ISNUMBER(Timeline!$F13)),I$4<=Timeline!$K13,EOMONTH(I$4,0)>=Timeline!$H13),"P",IF(AND(ISNUMBER(Timeline!$K13),ISNUMBER(Timeline!$O13),I$4<=Timeline!$O13,EOMONTH(I$4,0)>Timeline!$K13),"S","")))) -> P | J8: =IF(AND(ISNUMBER(Timeline!$E13),ISNUMBER(Timeline!$F13),J$4<=Timeline!$F13,EOMONTH(J$4,0)>=Timeline!$E13),"C",IF(AND(ISNUMBER(Timeline!$F13),ISNUMBER(Timeline!$K13),J$4<=Timeline!$K13,EOMONTH(J$4,0)>Timeline!$F13),"P",IF(AND(ISNUMBER(Timeline!$H13),ISNUMBER(Timeline!$K13),NOT(ISNUMBER(Timeline!$F13)),J$4<=Timeline!$K13,EOMONTH(J$4,0)>=Timeline!$H13),"P",IF(AND(ISNUMBER(Timeline!$K13),ISNUMBER(Timeline!$O13),J$4<=Timeline!$O13,EOMONTH(J$4,0)>Timeline!$K13),"S","")))) -> P | K8: =IF(AND(ISNUMBER(Timeline!$E13),ISNUMBER(Timeline!$F13),K$4<=Timeline!$F13,EOMONTH(K$4,0)>=Timeline!$E13),"C",IF(AND(ISNUMBER(Timeline!$F13),ISNUMBER(Timeline!$K13),K$4<=Timeline!$K13,EOMONTH(K$4,0)>Timeline!$F13),"P",IF(AND(ISNUMBER(Timeline!$H13),ISNUMBER(Timeline!$K13),NOT(ISNUMBER(Timeline!$F13)),K$4<=Timeline!$K13,EOMONTH(K$4,0)>=Timeline!$H13),"P",IF(AND(ISNUMBER(Timeline!$K13),ISNUMBER(Timeline!$O13),K$4<=Timeline!$O13,EOMONTH(K$4,0)>Timeline!$K13),"S","")))) -> P | ... AH8: =IF(AND(ISNUMBER(Timeline!$E13),ISNUMBER(Timeline!$F13),AH$4<=Timeline!$F13,EOMONTH(AH$4,0)>=Timeline!$E13),"C",IF(AND(ISNUMBER(Timeline!$F13),ISNUMBER(Timeline!$K13),AH$4<=Timeline!$K13,EOMONTH(AH$4,0)>Timeline!$F13),"P",IF(AND(ISNUMBER(Timeline!$H13),ISNUMBER(Timeline!$K13),NOT(ISNUMBER(Timeline!$F13)),AH$4<=Timeline!$K13,EOMONTH(AH$4,0)>=Timeline!$H13),"P",IF(AND(ISNUMBER(Timeline!$K13),ISNUMBER(Timeline!$O13),AH$4<=Timeline!$O13,EOMONTH(AH$4,0)>Timeline!$K13),"S",""))))
A9: 5 | B9: Customer Due Diligence (standard / simplified / enhanced) | C9: RTS | D9: =IF(AND(ISNUMBER(Timeline!$E14),ISNUMBER(Timeline!$F14),D$4<=Timeline!$F14,EOMONTH(D$4,0)>=Timeline!$E14),"C",IF(AND(ISNUMBER(Timeline!$F14),ISNUMBER(Timeline!$K14),D$4<=Timeline!$K14,EOMONTH(D$4,0)>Timeline!$F14),"P",IF(AND(ISNUMBER(Timeline!$H14),ISNUMBER(Timeline!$K14),NOT(ISNUMBER(Timeline!$F14)),D$4<=Timeline!$K14,EOMONTH(D$4,0)>=Timeline!$H14),"P",IF(AND(ISNUMBER(Timeline!$K14),ISNUMBER(Timeline!$O14),D$4<=Timeline!$O14,EOMONTH(D$4,0)>Timeline!$K14),"S","")))) | E9: =IF(AND(ISNUMBER(Timeline!$E14),ISNUMBER(Timeline!$F14),E$4<=Timeline!$F14,EOMONTH(E$4,0)>=Timeline!$E14),"C",IF(AND(ISNUMBER(Timeline!$F14),ISNUMBER(Timeline!$K14),E$4<=Timeline!$K14,EOMONTH(E$4,0)>Timeline!$F14),"P",IF(AND(ISNUMBER(Timeline!$H14),ISNUMBER(Timeline!$K14),NOT(ISNUMBER(Timeline!$F14)),E$4<=Timeline!$K14,EOMONTH(E$4,0)>=Timeline!$H14),"P",IF(AND(ISNUMBER(Timeline!$K14),ISNUMBER(Timeline!$O14),E$4<=Timeline!$O14,EOMONTH(E$4,0)>Timeline!$K14),"S","")))) | F9: =IF(AND(ISNUMBER(Timeline!$E14),ISNUMBER(Timeline!$F14),F$4<=Timeline!$F14,EOMONTH(F$4,0)>=Timeline!$E14),"C",IF(AND(ISNUMBER(Timeline!$F14),ISNUMBER(Timeline!$K14),F$4<=Timeline!$K14,EOMONTH(F$4,0)>Timeline!$F14),"P",IF(AND(ISNUMBER(Timeline!$H14),ISNUMBER(Timeline!$K14),NOT(ISNUMBER(Timeline!$F14)),F$4<=Timeline!$K14,EOMONTH(F$4,0)>=Timeline!$H14),"P",IF(AND(ISNUMBER(Timeline!$K14),ISNUMBER(Timeline!$O14),F$4<=Timeline!$O14,EOMONTH(F$4,0)>Timeline!$K14),"S","")))) -> C | G9: =IF(AND(ISNUMBER(Timeline!$E14),ISNUMBER(Timeline!$F14),G$4<=Timeline!$F14,EOMONTH(G$4,0)>=Timeline!$E14),"C",IF(AND(ISNUMBER(Timeline!$F14),ISNUMBER(Timeline!$K14),G$4<=Timeline!$K14,EOMONTH(G$4,0)>Timeline!$F14),"P",IF(AND(ISNUMBER(Timeline!$H14),ISNUMBER(Timeline!$K14),NOT(ISNUMBER(Timeline!$F14)),G$4<=Timeline!$K14,EOMONTH(G$4,0)>=Timeline!$H14),"P",IF(AND(ISNUMBER(Timeline!$K14),ISNUMBER(Timeline!$O14),G$4<=Timeline!$O14,EOMONTH(G$4,0)>Timeline!$K14),"S","")))) -> C | H9: =IF(AND(ISNUMBER(Timeline!$E14),ISNUMBER(Timeline!$F14),H$4<=Timeline!$F14,EOMONTH(H$4,0)>=Timeline!$E14),"C",IF(AND(ISNUMBER(Timeline!$F14),ISNUMBER(Timeline!$K14),H$4<=Timeline!$K14,EOMONTH(H$4,0)>Timeline!$F14),"P",IF(AND(ISNUMBER(Timeline!$H14),ISNUMBER(Timeline!$K14),NOT(ISNUMBER(Timeline!$F14)),H$4<=Timeline!$K14,EOMONTH(H$4,0)>=Timeline!$H14),"P",IF(AND(ISNUMBER(Timeline!$K14),ISNUMBER(Timeline!$O14),H$4<=Timeline!$O14,EOMONTH(H$4,0)>Timeline!$K14),"S","")))) -> C | I9: =IF(AND(ISNUMBER(Timeline!$E14),ISNUMBER(Timeline!$F14),I$4<=Timeline!$F14,EOMONTH(I$4,0)>=Timeline!$E14),"C",IF(AND(ISNUMBER(Timeline!$F14),ISNUMBER(Timeline!$K14),I$4<=Timeline!$K14,EOMONTH(I$4,0)>Timeline!$F14),"P",IF(AND(ISNUMBER(Timeline!$H14),ISNUMBER(Timeline!$K14),NOT(ISNUMBER(Timeline!$F14)),I$4<=Timeline!$K14,EOMONTH(I$4,0)>=Timeline!$H14),"P",IF(AND(ISNUMBER(Timeline!$K14),ISNUMBER(Timeline!$O14),I$4<=Timeline!$O14,EOMONTH(I$4,0)>Timeline!$K14),"S","")))) -> C | J9: =IF(AND(ISNUMBER(Timeline!$E14),ISNUMBER(Timeline!$F14),J$4<=Timeline!$F14,EOMONTH(J$4,0)>=Timeline!$E14),"C",IF(AND(ISNUMBER(Timeline!$F14),ISNUMBER(Timeline!$K14),J$4<=Timeline!$K14,EOMONTH(J$4,0)>Timeline!$F14),"P",IF(AND(ISNUMBER(Timeline!$H14),ISNUMBER(Timeline!$K14),NOT(ISNUMBER(Timeline!$F14)),J$4<=Timeline!$K14,EOMONTH(J$4,0)>=Timeline!$H14),"P",IF(AND(ISNUMBER(Timeline!$K14),ISNUMBER(Timeline!$O14),J$4<=Timeline!$O14,EOMONTH(J$4,0)>Timeline!$K14),"S","")))) -> P | K9: =IF(AND(ISNUMBER(Timeline!$E14),ISNUMBER(Timeline!$F14),K$4<=Timeline!$F14,EOMONTH(K$4,0)>=Timeline!$E14),"C",IF(AND(ISNUMBER(Timeline!$F14),ISNUMBER(Timeline!$K14),K$4<=Timeline!$K14,EOMONTH(K$4,0)>Timeline!$F14),"P",IF(AND(ISNUMBER(Timeline!$H14),ISNUMBER(Timeline!$K14),NOT(ISNUMBER(Timeline!$F14)),K$4<=Timeline!$K14,EOMONTH(K$4,0)>=Timeline!$H14),"P",IF(AND(ISNUMBER(Timeline!$K14),ISNUMBER(Timeline!$O14),K$4<=Timeline!$O14,EOMONTH(K$4,0)>Timeline!$K14),"S","")))) -> P | ... AH9: =IF(AND(ISNUMBER(Timeline!$E14),ISNUMBER(Timeline!$F14),AH$4<=Timeline!$F14,EOMONTH(AH$4,0)>=Timeline!$E14),"C",IF(AND(ISNUMBER(Timeline!$F14),ISNUMBER(Timeline!$K14),AH$4<=Timeline!$K14,EOMONTH(AH$4,0)>Timeline!$F14),"P",IF(AND(ISNUMBER(Timeline!$H14),ISNUMBER(Timeline!$K14),NOT(ISNUMBER(Timeline!$F14)),AH$4<=Timeline!$K14,EOMONTH(AH$4,0)>=Timeline!$H14),"P",IF(AND(ISNUMBER(Timeline!$K14),ISNUMBER(Timeline!$O14),AH$4<=Timeline!$O14,EOMONTH(AH$4,0)>Timeline!$K14),"S",""))))
A10: 6 | B10: Business relationships, occasional & linked transactions, lower thresholds | C10: RTS | D10: =IF(AND(ISNUMBER(Timeline!$E15),ISNUMBER(Timeline!$F15),D$4<=Timeline!$F15,EOMONTH(D$4,0)>=Timeline!$E15),"C",IF(AND(ISNUMBER(Timeline!$F15),ISNUMBER(Timeline!$K15),D$4<=Timeline!$K15,EOMONTH(D$4,0)>Timeline!$F15),"P",IF(AND(ISNUMBER(Timeline!$H15),ISNUMBER(Timeline!$K15),NOT(ISNUMBER(Timeline!$F15)),D$4<=Timeline!$K15,EOMONTH(D$4,0)>=Timeline!$H15),"P",IF(AND(ISNUMBER(Timeline!$K15),ISNUMBER(Timeline!$O15),D$4<=Timeline!$O15,EOMONTH(D$4,0)>Timeline!$K15),"S","")))) | E10: =IF(AND(ISNUMBER(Timeline!$E15),ISNUMBER(Timeline!$F15),E$4<=Timeline!$F15,EOMONTH(E$4,0)>=Timeline!$E15),"C",IF(AND(ISNUMBER(Timeline!$F15),ISNUMBER(Timeline!$K15),E$4<=Timeline!$K15,EOMONTH(E$4,0)>Timeline!$F15),"P",IF(AND(ISNUMBER(Timeline!$H15),ISNUMBER(Timeline!$K15),NOT(ISNUMBER(Timeline!$F15)),E$4<=Timeline!$K15,EOMONTH(E$4,0)>=Timeline!$H15),"P",IF(AND(ISNUMBER(Timeline!$K15),ISNUMBER(Timeline!$O15),E$4<=Timeline!$O15,EOMONTH(E$4,0)>Timeline!$K15),"S","")))) | F10: =IF(AND(ISNUMBER(Timeline!$E15),ISNUMBER(Timeline!$F15),F$4<=Timeline!$F15,EOMONTH(F$4,0)>=Timeline!$E15),"C",IF(AND(ISNUMBER(Timeline!$F15),ISNUMBER(Timeline!$K15),F$4<=Timeline!$K15,EOMONTH(F$4,0)>Timeline!$F15),"P",IF(AND(ISNUMBER(Timeline!$H15),ISNUMBER(Timeline!$K15),NOT(ISNUMBER(Timeline!$F15)),F$4<=Timeline!$K15,EOMONTH(F$4,0)>=Timeline!$H15),"P",IF(AND(ISNUMBER(Timeline!$K15),ISNUMBER(Timeline!$O15),F$4<=Timeline!$O15,EOMONTH(F$4,0)>Timeline!$K15),"S","")))) -> C | G10: =IF(AND(ISNUMBER(Timeline!$E15),ISNUMBER(Timeline!$F15),G$4<=Timeline!$F15,EOMONTH(G$4,0)>=Timeline!$E15),"C",IF(AND(ISNUMBER(Timeline!$F15),ISNUMBER(Timeline!$K15),G$4<=Timeline!$K15,EOMONTH(G$4,0)>Timeline!$F15),"P",IF(AND(ISNUMBER(Timeline!$H15),ISNUMBER(Timeline!$K15),NOT(ISNUMBER(Timeline!$F15)),G$4<=Timeline!$K15,EOMONTH(G$4,0)>=Timeline!$H15),"P",IF(AND(ISNUMBER(Timeline!$K15),ISNUMBER(Timeline!$O15),G$4<=Timeline!$O15,EOMONTH(G$4,0)>Timeline!$K15),"S","")))) -> C | H10: =IF(AND(ISNUMBER(Timeline!$E15),ISNUMBER(Timeline!$F15),H$4<=Timeline!$F15,EOMONTH(H$4,0)>=Timeline!$E15),"C",IF(AND(ISNUMBER(Timeline!$F15),ISNUMBER(Timeline!$K15),H$4<=Timeline!$K15,EOMONTH(H$4,0)>Timeline!$F15),"P",IF(AND(ISNUMBER(Timeline!$H15),ISNUMBER(Timeline!$K15),NOT(ISNUMBER(Timeline!$F15)),H$4<=Timeline!$K15,EOMONTH(H$4,0)>=Timeline!$H15),"P",IF(AND(ISNUMBER(Timeline!$K15),ISNUMBER(Timeline!$O15),H$4<=Timeline!$O15,EOMONTH(H$4,0)>Timeline!$K15),"S","")))) -> C | I10: =IF(AND(ISNUMBER(Timeline!$E15),ISNUMBER(Timeline!$F15),I$4<=Timeline!$F15,EOMONTH(I$4,0)>=Timeline!$E15),"C",IF(AND(ISNUMBER(Timeline!$F15),ISNUMBER(Timeline!$K15),I$4<=Timeline!$K15,EOMONTH(I$4,0)>Timeline!$F15),"P",IF(AND(ISNUMBER(Timeline!$H15),ISNUMBER(Timeline!$K15),NOT(ISNUMBER(Timeline!$F15)),I$4<=Timeline!$K15,EOMONTH(I$4,0)>=Timeline!$H15),"P",IF(AND(ISNUMBER(Timeline!$K15),ISNUMBER(Timeline!$O15),I$4<=Timeline!$O15,EOMONTH(I$4,0)>Timeline!$K15),"S","")))) -> C | J10: =IF(AND(ISNUMBER(Timeline!$E15),ISNUMBER(Timeline!$F15),J$4<=Timeline!$F15,EOMONTH(J$4,0)>=Timeline!$E15),"C",IF(AND(ISNUMBER(Timeline!$F15),ISNUMBER(Timeline!$K15),J$4<=Timeline!$K15,EOMONTH(J$4,0)>Timeline!$F15),"P",IF(AND(ISNUMBER(Timeline!$H15),ISNUMBER(Timeline!$K15),NOT(ISNUMBER(Timeline!$F15)),J$4<=Timeline!$K15,EOMONTH(J$4,0)>=Timeline!$H15),"P",IF(AND(ISNUMBER(Timeline!$K15),ISNUMBER(Timeline!$O15),J$4<=Timeline!$O15,EOMONTH(J$4,0)>Timeline!$K15),"S","")))) -> P | K10: =IF(AND(ISNUMBER(Timeline!$E15),ISNUMBER(Timeline!$F15),K$4<=Timeline!$F15,EOMONTH(K$4,0)>=Timeline!$E15),"C",IF(AND(ISNUMBER(Timeline!$F15),ISNUMBER(Timeline!$K15),K$4<=Timeline!$K15,EOMONTH(K$4,0)>Timeline!$F15),"P",IF(AND(ISNUMBER(Timeline!$H15),ISNUMBER(Timeline!$K15),NOT(ISNUMBER(Timeline!$F15)),K$4<=Timeline!$K15,EOMONTH(K$4,0)>=Timeline!$H15),"P",IF(AND(ISNUMBER(Timeline!$K15),ISNUMBER(Timeline!$O15),K$4<=Timeline!$O15,EOMONTH(K$4,0)>Timeline!$K15),"S","")))) -> P | ... AH10: =IF(AND(ISNUMBER(Timeline!$E15),ISNUMBER(Timeline!$F15),AH$4<=Timeline!$F15,EOMONTH(AH$4,0)>=Timeline!$E15),"C",IF(AND(ISNUMBER(Timeline!$F15),ISNUMBER(Timeline!$K15),AH$4<=Timeline!$K15,EOMONTH(AH$4,0)>Timeline!$F15),"P",IF(AND(ISNUMBER(Timeline!$H15),ISNUMBER(Timeline!$K15),NOT(ISNUMBER(Timeline!$F15)),AH$4<=Timeline!$K15,EOMONTH(AH$4,0)>=Timeline!$H15),"P",IF(AND(ISNUMBER(Timeline!$K15),ISNUMBER(Timeline!$O15),AH$4<=Timeline!$O15,EOMONTH(AH$4,0)>Timeline!$K15),"S",""))))
A11: 7 | B11: Group-wide minimum requirements; third-country branches/subsidiaries | C11: RTS | D11: =IF(AND(ISNUMBER(Timeline!$E16),ISNUMBER(Timeline!$F16),D$4<=Timeline!$F16,EOMONTH(D$4,0)>=Timeline!$E16),"C",IF(AND(ISNUMBER(Timeline!$F16),ISNUMBER(Timeline!$K16),D$4<=Timeline!$K16,EOMONTH(D$4,0)>Timeline!$F16),"P",IF(AND(ISNUMBER(Timeline!$H16),ISNUMBER(Timeline!$K16),NOT(ISNUMBER(Timeline!$F16)),D$4<=Timeline!$K16,EOMONTH(D$4,0)>=Timeline!$H16),"P",IF(AND(ISNUMBER(Timeline!$K16),ISNUMBER(Timeline!$O16),D$4<=Timeline!$O16,EOMONTH(D$4,0)>Timeline!$K16),"S","")))) | E11: =IF(AND(ISNUMBER(Timeline!$E16),ISNUMBER(Timeline!$F16),E$4<=Timeline!$F16,EOMONTH(E$4,0)>=Timeline!$E16),"C",IF(AND(ISNUMBER(Timeline!$F16),ISNUMBER(Timeline!$K16),E$4<=Timeline!$K16,EOMONTH(E$4,0)>Timeline!$F16),"P",IF(AND(ISNUMBER(Timeline!$H16),ISNUMBER(Timeline!$K16),NOT(ISNUMBER(Timeline!$F16)),E$4<=Timeline!$K16,EOMONTH(E$4,0)>=Timeline!$H16),"P",IF(AND(ISNUMBER(Timeline!$K16),ISNUMBER(Timeline!$O16),E$4<=Timeline!$O16,EOMONTH(E$4,0)>Timeline!$K16),"S","")))) | F11: =IF(AND(ISNUMBER(Timeline!$E16),ISNUMBER(Timeline!$F16),F$4<=Timeline!$F16,EOMONTH(F$4,0)>=Timeline!$E16),"C",IF(AND(ISNUMBER(Timeline!$F16),ISNUMBER(Timeline!$K16),F$4<=Timeline!$K16,EOMONTH(F$4,0)>Timeline!$F16),"P",IF(AND(ISNUMBER(Timeline!$H16),ISNUMBER(Timeline!$K16),NOT(ISNUMBER(Timeline!$F16)),F$4<=Timeline!$K16,EOMONTH(F$4,0)>=Timeline!$H16),"P",IF(AND(ISNUMBER(Timeline!$K16),ISNUMBER(Timeline!$O16),F$4<=Timeline!$O16,EOMONTH(F$4,0)>Timeline!$K16),"S","")))) | G11: =IF(AND(ISNUMBER(Timeline!$E16),ISNUMBER(Timeline!$F16),G$4<=Timeline!$F16,EOMONTH(G$4,0)>=Timeline!$E16),"C",IF(AND(ISNUMBER(Timeline!$F16),ISNUMBER(Timeline!$K16),G$4<=Timeline!$K16,EOMONTH(G$4,0)>Timeline!$F16),"P",IF(AND(ISNUMBER(Timeline!$H16),ISNUMBER(Timeline!$K16),NOT(ISNUMBER(Timeline!$F16)),G$4<=Timeline!$K16,EOMONTH(G$4,0)>=Timeline!$H16),"P",IF(AND(ISNUMBER(Timeline!$K16),ISNUMBER(Timeline!$O16),G$4<=Timeline!$O16,EOMONTH(G$4,0)>Timeline!$K16),"S","")))) | H11: =IF(AND(ISNUMBER(Timeline!$E16),ISNUMBER(Timeline!$F16),H$4<=Timeline!$F16,EOMONTH(H$4,0)>=Timeline!$E16),"C",IF(AND(ISNUMBER(Timeline!$F16),ISNUMBER(Timeline!$K16),H$4<=Timeline!$K16,EOMONTH(H$4,0)>Timeline!$F16),"P",IF(AND(ISNUMBER(Timeline!$H16),ISNUMBER(Timeline!$K16),NOT(ISNUMBER(Timeline!$F16)),H$4<=Timeline!$K16,EOMONTH(H$4,0)>=Timeline!$H16),"P",IF(AND(ISNUMBER(Timeline!$K16),ISNUMBER(Timeline!$O16),H$4<=Timeline!$O16,EOMONTH(H$4,0)>Timeline!$K16),"S","")))) -> C | I11: =IF(AND(ISNUMBER(Timeline!$E16),ISNUMBER(Timeline!$F16),I$4<=Timeline!$F16,EOMONTH(I$4,0)>=Timeline!$E16),"C",IF(AND(ISNUMBER(Timeline!$F16),ISNUMBER(Timeline!$K16),I$4<=Timeline!$K16,EOMONTH(I$4,0)>Timeline!$F16),"P",IF(AND(ISNUMBER(Timeline!$H16),ISNUMBER(Timeline!$K16),NOT(ISNUMBER(Timeline!$F16)),I$4<=Timeline!$K16,EOMONTH(I$4,0)>=Timeline!$H16),"P",IF(AND(ISNUMBER(Timeline!$K16),ISNUMBER(Timeline!$O16),I$4<=Timeline!$O16,EOMONTH(I$4,0)>Timeline!$K16),"S","")))) -> C | J11: =IF(AND(ISNUMBER(Timeline!$E16),ISNUMBER(Timeline!$F16),J$4<=Timeline!$F16,EOMONTH(J$4,0)>=Timeline!$E16),"C",IF(AND(ISNUMBER(Timeline!$F16),ISNUMBER(Timeline!$K16),J$4<=Timeline!$K16,EOMONTH(J$4,0)>Timeline!$F16),"P",IF(AND(ISNUMBER(Timeline!$H16),ISNUMBER(Timeline!$K16),NOT(ISNUMBER(Timeline!$F16)),J$4<=Timeline!$K16,EOMONTH(J$4,0)>=Timeline!$H16),"P",IF(AND(ISNUMBER(Timeline!$K16),ISNUMBER(Timeline!$O16),J$4<=Timeline!$O16,EOMONTH(J$4,0)>Timeline!$K16),"S","")))) -> C | K11: =IF(AND(ISNUMBER(Timeline!$E16),ISNUMBER(Timeline!$F16),K$4<=Timeline!$F16,EOMONTH(K$4,0)>=Timeline!$E16),"C",IF(AND(ISNUMBER(Timeline!$F16),ISNUMBER(Timeline!$K16),K$4<=Timeline!$K16,EOMONTH(K$4,0)>Timeline!$F16),"P",IF(AND(ISNUMBER(Timeline!$H16),ISNUMBER(Timeline!$K16),NOT(ISNUMBER(Timeline!$F16)),K$4<=Timeline!$K16,EOMONTH(K$4,0)>=Timeline!$H16),"P",IF(AND(ISNUMBER(Timeline!$K16),ISNUMBER(Timeline!$O16),K$4<=Timeline!$O16,EOMONTH(K$4,0)>Timeline!$K16),"S","")))) -> P | ... AH11: =IF(AND(ISNUMBER(Timeline!$E16),ISNUMBER(Timeline!$F16),AH$4<=Timeline!$F16,EOMONTH(AH$4,0)>=Timeline!$E16),"C",IF(AND(ISNUMBER(Timeline!$F16),ISNUMBER(Timeline!$K16),AH$4<=Timeline!$K16,EOMONTH(AH$4,0)>Timeline!$F16),"P",IF(AND(ISNUMBER(Timeline!$H16),ISNUMBER(Timeline!$K16),NOT(ISNUMBER(Timeline!$F16)),AH$4<=Timeline!$K16,EOMONTH(AH$4,0)>=Timeline!$H16),"P",IF(AND(ISNUMBER(Timeline!$K16),ISNUMBER(Timeline!$O16),AH$4<=Timeline!$O16,EOMONTH(AH$4,0)>Timeline!$K16),"S",""))))
A12: 8 | B12: FIU and AMLA reporting to the EPPO | C12: ITS | D12: =IF(AND(ISNUMBER(Timeline!$E17),ISNUMBER(Timeline!$F17),D$4<=Timeline!$F17,EOMONTH(D$4,0)>=Timeline!$E17),"C",IF(AND(ISNUMBER(Timeline!$F17),ISNUMBER(Timeline!$K17),D$4<=Timeline!$K17,EOMONTH(D$4,0)>Timeline!$F17),"P",IF(AND(ISNUMBER(Timeline!$H17),ISNUMBER(Timeline!$K17),NOT(ISNUMBER(Timeline!$F17)),D$4<=Timeline!$K17,EOMONTH(D$4,0)>=Timeline!$H17),"P",IF(AND(ISNUMBER(Timeline!$K17),ISNUMBER(Timeline!$O17),D$4<=Timeline!$O17,EOMONTH(D$4,0)>Timeline!$K17),"S","")))) | E12: =IF(AND(ISNUMBER(Timeline!$E17),ISNUMBER(Timeline!$F17),E$4<=Timeline!$F17,EOMONTH(E$4,0)>=Timeline!$E17),"C",IF(AND(ISNUMBER(Timeline!$F17),ISNUMBER(Timeline!$K17),E$4<=Timeline!$K17,EOMONTH(E$4,0)>Timeline!$F17),"P",IF(AND(ISNUMBER(Timeline!$H17),ISNUMBER(Timeline!$K17),NOT(ISNUMBER(Timeline!$F17)),E$4<=Timeline!$K17,EOMONTH(E$4,0)>=Timeline!$H17),"P",IF(AND(ISNUMBER(Timeline!$K17),ISNUMBER(Timeline!$O17),E$4<=Timeline!$O17,EOMONTH(E$4,0)>Timeline!$K17),"S","")))) | F12: =IF(AND(ISNUMBER(Timeline!$E17),ISNUMBER(Timeline!$F17),F$4<=Timeline!$F17,EOMONTH(F$4,0)>=Timeline!$E17),"C",IF(AND(ISNUMBER(Timeline!$F17),ISNUMBER(Timeline!$K17),F$4<=Timeline!$K17,EOMONTH(F$4,0)>Timeline!$F17),"P",IF(AND(ISNUMBER(Timeline!$H17),ISNUMBER(Timeline!$K17),NOT(ISNUMBER(Timeline!$F17)),F$4<=Timeline!$K17,EOMONTH(F$4,0)>=Timeline!$H17),"P",IF(AND(ISNUMBER(Timeline!$K17),ISNUMBER(Timeline!$O17),F$4<=Timeline!$O17,EOMONTH(F$4,0)>Timeline!$K17),"S","")))) | G12: =IF(AND(ISNUMBER(Timeline!$E17),ISNUMBER(Timeline!$F17),G$4<=Timeline!$F17,EOMONTH(G$4,0)>=Timeline!$E17),"C",IF(AND(ISNUMBER(Timeline!$F17),ISNUMBER(Timeline!$K17),G$4<=Timeline!$K17,EOMONTH(G$4,0)>Timeline!$F17),"P",IF(AND(ISNUMBER(Timeline!$H17),ISNUMBER(Timeline!$K17),NOT(ISNUMBER(Timeline!$F17)),G$4<=Timeline!$K17,EOMONTH(G$4,0)>=Timeline!$H17),"P",IF(AND(ISNUMBER(Timeline!$K17),ISNUMBER(Timeline!$O17),G$4<=Timeline!$O17,EOMONTH(G$4,0)>Timeline!$K17),"S","")))) | H12: =IF(AND(ISNUMBER(Timeline!$E17),ISNUMBER(Timeline!$F17),H$4<=Timeline!$F17,EOMONTH(H$4,0)>=Timeline!$E17),"C",IF(AND(ISNUMBER(Timeline!$F17),ISNUMBER(Timeline!$K17),H$4<=Timeline!$K17,EOMONTH(H$4,0)>Timeline!$F17),"P",IF(AND(ISNUMBER(Timeline!$H17),ISNUMBER(Timeline!$K17),NOT(ISNUMBER(Timeline!$F17)),H$4<=Timeline!$K17,EOMONTH(H$4,0)>=Timeline!$H17),"P",IF(AND(ISNUMBER(Timeline!$K17),ISNUMBER(Timeline!$O17),H$4<=Timeline!$O17,EOMONTH(H$4,0)>Timeline!$K17),"S","")))) | I12: =IF(AND(ISNUMBER(Timeline!$E17),ISNUMBER(Timeline!$F17),I$4<=Timeline!$F17,EOMONTH(I$4,0)>=Timeline!$E17),"C",IF(AND(ISNUMBER(Timeline!$F17),ISNUMBER(Timeline!$K17),I$4<=Timeline!$K17,EOMONTH(I$4,0)>Timeline!$F17),"P",IF(AND(ISNUMBER(Timeline!$H17),ISNUMBER(Timeline!$K17),NOT(ISNUMBER(Timeline!$F17)),I$4<=Timeline!$K17,EOMONTH(I$4,0)>=Timeline!$H17),"P",IF(AND(ISNUMBER(Timeline!$K17),ISNUMBER(Timeline!$O17),I$4<=Timeline!$O17,EOMONTH(I$4,0)>Timeline!$K17),"S","")))) | J12: =IF(AND(ISNUMBER(Timeline!$E17),ISNUMBER(Timeline!$F17),J$4<=Timeline!$F17,EOMONTH(J$4,0)>=Timeline!$E17),"C",IF(AND(ISNUMBER(Timeline!$F17),ISNUMBER(Timeline!$K17),J$4<=Timeline!$K17,EOMONTH(J$4,0)>Timeline!$F17),"P",IF(AND(ISNUMBER(Timeline!$H17),ISNUMBER(Timeline!$K17),NOT(ISNUMBER(Timeline!$F17)),J$4<=Timeline!$K17,EOMONTH(J$4,0)>=Timeline!$H17),"P",IF(AND(ISNUMBER(Timeline!$K17),ISNUMBER(Timeline!$O17),J$4<=Timeline!$O17,EOMONTH(J$4,0)>Timeline!$K17),"S","")))) -> P | K12: =IF(AND(ISNUMBER(Timeline!$E17),ISNUMBER(Timeline!$F17),K$4<=Timeline!$F17,EOMONTH(K$4,0)>=Timeline!$E17),"C",IF(AND(ISNUMBER(Timeline!$F17),ISNUMBER(Timeline!$K17),K$4<=Timeline!$K17,EOMONTH(K$4,0)>Timeline!$F17),"P",IF(AND(ISNUMBER(Timeline!$H17),ISNUMBER(Timeline!$K17),NOT(ISNUMBER(Timeline!$F17)),K$4<=Timeline!$K17,EOMONTH(K$4,0)>=Timeline!$H17),"P",IF(AND(ISNUMBER(Timeline!$K17),ISNUMBER(Timeline!$O17),K$4<=Timeline!$O17,EOMONTH(K$4,0)>Timeline!$K17),"S","")))) -> P | ... AH12: =IF(AND(ISNUMBER(Timeline!$E17),ISNUMBER(Timeline!$F17),AH$4<=Timeline!$F17,EOMONTH(AH$4,0)>=Timeline!$E17),"C",IF(AND(ISNUMBER(Timeline!$F17),ISNUMBER(Timeline!$K17),AH$4<=Timeline!$K17,EOMONTH(AH$4,0)>Timeline!$F17),"P",IF(AND(ISNUMBER(Timeline!$H17),ISNUMBER(Timeline!$K17),NOT(ISNUMBER(Timeline!$F17)),AH$4<=Timeline!$K17,EOMONTH(AH$4,0)>=Timeline!$H17),"P",IF(AND(ISNUMBER(Timeline!$K17),ISNUMBER(Timeline!$O17),AH$4<=Timeline!$O17,EOMONTH(AH$4,0)>Timeline!$K17),"S",""))))
A13: 9 | B13: FIU-to-FIU exchange format | C13: ITS | D13: =IF(AND(ISNUMBER(Timeline!$E18),ISNUMBER(Timeline!$F18),D$4<=Timeline!$F18,EOMONTH(D$4,0)>=Timeline!$E18),"C",IF(AND(ISNUMBER(Timeline!$F18),ISNUMBER(Timeline!$K18),D$4<=Timeline!$K18,EOMONTH(D$4,0)>Timeline!$F18),"P",IF(AND(ISNUMBER(Timeline!$H18),ISNUMBER(Timeline!$K18),NOT(ISNUMBER(Timeline!$F18)),D$4<=Timeline!$K18,EOMONTH(D$4,0)>=Timeline!$H18),"P",IF(AND(ISNUMBER(Timeline!$K18),ISNUMBER(Timeline!$O18),D$4<=Timeline!$O18,EOMONTH(D$4,0)>Timeline!$K18),"S","")))) | E13: =IF(AND(ISNUMBER(Timeline!$E18),ISNUMBER(Timeline!$F18),E$4<=Timeline!$F18,EOMONTH(E$4,0)>=Timeline!$E18),"C",IF(AND(ISNUMBER(Timeline!$F18),ISNUMBER(Timeline!$K18),E$4<=Timeline!$K18,EOMONTH(E$4,0)>Timeline!$F18),"P",IF(AND(ISNUMBER(Timeline!$H18),ISNUMBER(Timeline!$K18),NOT(ISNUMBER(Timeline!$F18)),E$4<=Timeline!$K18,EOMONTH(E$4,0)>=Timeline!$H18),"P",IF(AND(ISNUMBER(Timeline!$K18),ISNUMBER(Timeline!$O18),E$4<=Timeline!$O18,EOMONTH(E$4,0)>Timeline!$K18),"S","")))) | F13: =IF(AND(ISNUMBER(Timeline!$E18),ISNUMBER(Timeline!$F18),F$4<=Timeline!$F18,EOMONTH(F$4,0)>=Timeline!$E18),"C",IF(AND(ISNUMBER(Timeline!$F18),ISNUMBER(Timeline!$K18),F$4<=Timeline!$K18,EOMONTH(F$4,0)>Timeline!$F18),"P",IF(AND(ISNUMBER(Timeline!$H18),ISNUMBER(Timeline!$K18),NOT(ISNUMBER(Timeline!$F18)),F$4<=Timeline!$K18,EOMONTH(F$4,0)>=Timeline!$H18),"P",IF(AND(ISNUMBER(Timeline!$K18),ISNUMBER(Timeline!$O18),F$4<=Timeline!$O18,EOMONTH(F$4,0)>Timeline!$K18),"S","")))) | G13: =IF(AND(ISNUMBER(Timeline!$E18),ISNUMBER(Timeline!$F18),G$4<=Timeline!$F18,EOMONTH(G$4,0)>=Timeline!$E18),"C",IF(AND(ISNUMBER(Timeline!$F18),ISNUMBER(Timeline!$K18),G$4<=Timeline!$K18,EOMONTH(G$4,0)>Timeline!$F18),"P",IF(AND(ISNUMBER(Timeline!$H18),ISNUMBER(Timeline!$K18),NOT(ISNUMBER(Timeline!$F18)),G$4<=Timeline!$K18,EOMONTH(G$4,0)>=Timeline!$H18),"P",IF(AND(ISNUMBER(Timeline!$K18),ISNUMBER(Timeline!$O18),G$4<=Timeline!$O18,EOMONTH(G$4,0)>Timeline!$K18),"S","")))) | H13: =IF(AND(ISNUMBER(Timeline!$E18),ISNUMBER(Timeline!$F18),H$4<=Timeline!$F18,EOMONTH(H$4,0)>=Timeline!$E18),"C",IF(AND(ISNUMBER(Timeline!$F18),ISNUMBER(Timeline!$K18),H$4<=Timeline!$K18,EOMONTH(H$4,0)>Timeline!$F18),"P",IF(AND(ISNUMBER(Timeline!$H18),ISNUMBER(Timeline!$K18),NOT(ISNUMBER(Timeline!$F18)),H$4<=Timeline!$K18,EOMONTH(H$4,0)>=Timeline!$H18),"P",IF(AND(ISNUMBER(Timeline!$K18),ISNUMBER(Timeline!$O18),H$4<=Timeline!$O18,EOMONTH(H$4,0)>Timeline!$K18),"S","")))) | I13: =IF(AND(ISNUMBER(Timeline!$E18),ISNUMBER(Timeline!$F18),I$4<=Timeline!$F18,EOMONTH(I$4,0)>=Timeline!$E18),"C",IF(AND(ISNUMBER(Timeline!$F18),ISNUMBER(Timeline!$K18),I$4<=Timeline!$K18,EOMONTH(I$4,0)>Timeline!$F18),"P",IF(AND(ISNUMBER(Timeline!$H18),ISNUMBER(Timeline!$K18),NOT(ISNUMBER(Timeline!$F18)),I$4<=Timeline!$K18,EOMONTH(I$4,0)>=Timeline!$H18),"P",IF(AND(ISNUMBER(Timeline!$K18),ISNUMBER(Timeline!$O18),I$4<=Timeline!$O18,EOMONTH(I$4,0)>Timeline!$K18),"S","")))) | J13: =IF(AND(ISNUMBER(Timeline!$E18),ISNUMBER(Timeline!$F18),J$4<=Timeline!$F18,EOMONTH(J$4,0)>=Timeline!$E18),"C",IF(AND(ISNUMBER(Timeline!$F18),ISNUMBER(Timeline!$K18),J$4<=Timeline!$K18,EOMONTH(J$4,0)>Timeline!$F18),"P",IF(AND(ISNUMBER(Timeline!$H18),ISNUMBER(Timeline!$K18),NOT(ISNUMBER(Timeline!$F18)),J$4<=Timeline!$K18,EOMONTH(J$4,0)>=Timeline!$H18),"P",IF(AND(ISNUMBER(Timeline!$K18),ISNUMBER(Timeline!$O18),J$4<=Timeline!$O18,EOMONTH(J$4,0)>Timeline!$K18),"S","")))) -> P | K13: =IF(AND(ISNUMBER(Timeline!$E18),ISNUMBER(Timeline!$F18),K$4<=Timeline!$F18,EOMONTH(K$4,0)>=Timeline!$E18),"C",IF(AND(ISNUMBER(Timeline!$F18),ISNUMBER(Timeline!$K18),K$4<=Timeline!$K18,EOMONTH(K$4,0)>Timeline!$F18),"P",IF(AND(ISNUMBER(Timeline!$H18),ISNUMBER(Timeline!$K18),NOT(ISNUMBER(Timeline!$F18)),K$4<=Timeline!$K18,EOMONTH(K$4,0)>=Timeline!$H18),"P",IF(AND(ISNUMBER(Timeline!$K18),ISNUMBER(Timeline!$O18),K$4<=Timeline!$O18,EOMONTH(K$4,0)>Timeline!$K18),"S","")))) -> P | ... AH13: =IF(AND(ISNUMBER(Timeline!$E18),ISNUMBER(Timeline!$F18),AH$4<=Timeline!$F18,EOMONTH(AH$4,0)>=Timeline!$E18),"C",IF(AND(ISNUMBER(Timeline!$F18),ISNUMBER(Timeline!$K18),AH$4<=Timeline!$K18,EOMONTH(AH$4,0)>Timeline!$F18),"P",IF(AND(ISNUMBER(Timeline!$H18),ISNUMBER(Timeline!$K18),NOT(ISNUMBER(Timeline!$F18)),AH$4<=Timeline!$K18,EOMONTH(AH$4,0)>=Timeline!$H18),"P",IF(AND(ISNUMBER(Timeline!$K18),ISNUMBER(Timeline!$O18),AH$4<=Timeline!$O18,EOMONTH(AH$4,0)>Timeline!$K18),"S",""))))
A14: 10 | B14: Home-host supervisory cooperation | C14: RTS | D14: =IF(AND(ISNUMBER(Timeline!$E19),ISNUMBER(Timeline!$F19),D$4<=Timeline!$F19,EOMONTH(D$4,0)>=Timeline!$E19),"C",IF(AND(ISNUMBER(Timeline!$F19),ISNUMBER(Timeline!$K19),D$4<=Timeline!$K19,EOMONTH(D$4,0)>Timeline!$F19),"P",IF(AND(ISNUMBER(Timeline!$H19),ISNUMBER(Timeline!$K19),NOT(ISNUMBER(Timeline!$F19)),D$4<=Timeline!$K19,EOMONTH(D$4,0)>=Timeline!$H19),"P",IF(AND(ISNUMBER(Timeline!$K19),ISNUMBER(Timeline!$O19),D$4<=Timeline!$O19,EOMONTH(D$4,0)>Timeline!$K19),"S","")))) | E14: =IF(AND(ISNUMBER(Timeline!$E19),ISNUMBER(Timeline!$F19),E$4<=Timeline!$F19,EOMONTH(E$4,0)>=Timeline!$E19),"C",IF(AND(ISNUMBER(Timeline!$F19),ISNUMBER(Timeline!$K19),E$4<=Timeline!$K19,EOMONTH(E$4,0)>Timeline!$F19),"P",IF(AND(ISNUMBER(Timeline!$H19),ISNUMBER(Timeline!$K19),NOT(ISNUMBER(Timeline!$F19)),E$4<=Timeline!$K19,EOMONTH(E$4,0)>=Timeline!$H19),"P",IF(AND(ISNUMBER(Timeline!$K19),ISNUMBER(Timeline!$O19),E$4<=Timeline!$O19,EOMONTH(E$4,0)>Timeline!$K19),"S","")))) | F14: =IF(AND(ISNUMBER(Timeline!$E19),ISNUMBER(Timeline!$F19),F$4<=Timeline!$F19,EOMONTH(F$4,0)>=Timeline!$E19),"C",IF(AND(ISNUMBER(Timeline!$F19),ISNUMBER(Timeline!$K19),F$4<=Timeline!$K19,EOMONTH(F$4,0)>Timeline!$F19),"P",IF(AND(ISNUMBER(Timeline!$H19),ISNUMBER(Timeline!$K19),NOT(ISNUMBER(Timeline!$F19)),F$4<=Timeline!$K19,EOMONTH(F$4,0)>=Timeline!$H19),"P",IF(AND(ISNUMBER(Timeline!$K19),ISNUMBER(Timeline!$O19),F$4<=Timeline!$O19,EOMONTH(F$4,0)>Timeline!$K19),"S","")))) | G14: =IF(AND(ISNUMBER(Timeline!$E19),ISNUMBER(Timeline!$F19),G$4<=Timeline!$F19,EOMONTH(G$4,0)>=Timeline!$E19),"C",IF(AND(ISNUMBER(Timeline!$F19),ISNUMBER(Timeline!$K19),G$4<=Timeline!$K19,EOMONTH(G$4,0)>Timeline!$F19),"P",IF(AND(ISNUMBER(Timeline!$H19),ISNUMBER(Timeline!$K19),NOT(ISNUMBER(Timeline!$F19)),G$4<=Timeline!$K19,EOMONTH(G$4,0)>=Timeline!$H19),"P",IF(AND(ISNUMBER(Timeline!$K19),ISNUMBER(Timeline!$O19),G$4<=Timeline!$O19,EOMONTH(G$4,0)>Timeline!$K19),"S","")))) | H14: =IF(AND(ISNUMBER(Timeline!$E19),ISNUMBER(Timeline!$F19),H$4<=Timeline!$F19,EOMONTH(H$4,0)>=Timeline!$E19),"C",IF(AND(ISNUMBER(Timeline!$F19),ISNUMBER(Timeline!$K19),H$4<=Timeline!$K19,EOMONTH(H$4,0)>Timeline!$F19),"P",IF(AND(ISNUMBER(Timeline!$H19),ISNUMBER(Timeline!$K19),NOT(ISNUMBER(Timeline!$F19)),H$4<=Timeline!$K19,EOMONTH(H$4,0)>=Timeline!$H19),"P",IF(AND(ISNUMBER(Timeline!$K19),ISNUMBER(Timeline!$O19),H$4<=Timeline!$O19,EOMONTH(H$4,0)>Timeline!$K19),"S","")))) | I14: =IF(AND(ISNUMBER(Timeline!$E19),ISNUMBER(Timeline!$F19),I$4<=Timeline!$F19,EOMONTH(I$4,0)>=Timeline!$E19),"C",IF(AND(ISNUMBER(Timeline!$F19),ISNUMBER(Timeline!$K19),I$4<=Timeline!$K19,EOMONTH(I$4,0)>Timeline!$F19),"P",IF(AND(ISNUMBER(Timeline!$H19),ISNUMBER(Timeline!$K19),NOT(ISNUMBER(Timeline!$F19)),I$4<=Timeline!$K19,EOMONTH(I$4,0)>=Timeline!$H19),"P",IF(AND(ISNUMBER(Timeline!$K19),ISNUMBER(Timeline!$O19),I$4<=Timeline!$O19,EOMONTH(I$4,0)>Timeline!$K19),"S","")))) | J14: =IF(AND(ISNUMBER(Timeline!$E19),ISNUMBER(Timeline!$F19),J$4<=Timeline!$F19,EOMONTH(J$4,0)>=Timeline!$E19),"C",IF(AND(ISNUMBER(Timeline!$F19),ISNUMBER(Timeline!$K19),J$4<=Timeline!$K19,EOMONTH(J$4,0)>Timeline!$F19),"P",IF(AND(ISNUMBER(Timeline!$H19),ISNUMBER(Timeline!$K19),NOT(ISNUMBER(Timeline!$F19)),J$4<=Timeline!$K19,EOMONTH(J$4,0)>=Timeline!$H19),"P",IF(AND(ISNUMBER(Timeline!$K19),ISNUMBER(Timeline!$O19),J$4<=Timeline!$O19,EOMONTH(J$4,0)>Timeline!$K19),"S","")))) -> P | K14: =IF(AND(ISNUMBER(Timeline!$E19),ISNUMBER(Timeline!$F19),K$4<=Timeline!$F19,EOMONTH(K$4,0)>=Timeline!$E19),"C",IF(AND(ISNUMBER(Timeline!$F19),ISNUMBER(Timeline!$K19),K$4<=Timeline!$K19,EOMONTH(K$4,0)>Timeline!$F19),"P",IF(AND(ISNUMBER(Timeline!$H19),ISNUMBER(Timeline!$K19),NOT(ISNUMBER(Timeline!$F19)),K$4<=Timeline!$K19,EOMONTH(K$4,0)>=Timeline!$H19),"P",IF(AND(ISNUMBER(Timeline!$K19),ISNUMBER(Timeline!$O19),K$4<=Timeline!$O19,EOMONTH(K$4,0)>Timeline!$K19),"S","")))) -> P | ... AH14: =IF(AND(ISNUMBER(Timeline!$E19),ISNUMBER(Timeline!$F19),AH$4<=Timeline!$F19,EOMONTH(AH$4,0)>=Timeline!$E19),"C",IF(AND(ISNUMBER(Timeline!$F19),ISNUMBER(Timeline!$K19),AH$4<=Timeline!$K19,EOMONTH(AH$4,0)>Timeline!$F19),"P",IF(AND(ISNUMBER(Timeline!$H19),ISNUMBER(Timeline!$K19),NOT(ISNUMBER(Timeline!$F19)),AH$4<=Timeline!$K19,EOMONTH(AH$4,0)>=Timeline!$H19),"P",IF(AND(ISNUMBER(Timeline!$K19),ISNUMBER(Timeline!$O19),AH$4<=Timeline!$O19,EOMONTH(AH$4,0)>Timeline!$K19),"S",""))))
